<?xml version="1.0" encoding="utf-8"?>
<!-- This URDF was automatically created by SolidWorks to URDF Exporter! Originally created by Stephen Brawner (brawner@gmail.com) 
     Commit Version: 1.5.1-0-g916b5db  Build Version: 1.5.7152.31018
     For more information, please see http://wiki.ros.org/sw_urdf_exporter -->
<robot
  name="rm_single">
  <link
    name="base_link">
    <inertial>
      <origin
        xyz="-3.7408 3.5756 0.26492"
        rpy="0 0 0" />
      <mass
        value="11153" />
      <inertia
        ixx="35963"
        ixy="1127.8"
        ixz="719.35"
        iyy="122460"
        iyz="564.03"
        izz="156540" />
    </inertial>
    <visual>
      <origin
        xyz="0 0 0"
        rpy="0 0 0" />
      <geometry>
        <mesh
          filename="package://rm_single/meshes/base_link.STL" />
      </geometry>
      <material
        name="">
        <color
          rgba="0.66667 0.66667 0.66667 1" />
      </material>
    </visual>
    <collision>
      <origin
        xyz="0 0 0"
        rpy="0 0 0" />
      <geometry>
        <mesh
          filename="package://rm_single/meshes/base_link.STL" />
      </geometry>
    </collision>
  </link>
  <link
    name="link_signal">
    <inertial>
      <origin
        xyz="-2.2204E-14 -2.2204E-16 -0.045571"
        rpy="0 0 0" />
      <mass
        value="19.215" />
      <inertia
        ixx="2.0802"
        ixy="-1.8332E-14"
        ixz="7.1733E-15"
        iyy="2.0802"
        iyz="1.0537E-16"
        izz="4.1547" />
    </inertial>
    <visual>
      <origin
        xyz="0 0 0"
        rpy="0 0 0" />
      <geometry>
        <mesh
          filename="package://rm_single/meshes/link_signal.STL" />
      </geometry>
      <material
        name="">
        <color
          rgba="0.20392 0.20392 0.20392 1" />
      </material>
    </visual>
    <collision>
      <origin
        xyz="0 0 0"
        rpy="0 0 0" />
      <geometry>
        <mesh
          filename="package://rm_single/meshes/link_signal.STL" />
      </geometry>
    </collision>
  </link>
  <joint
    name="joint_signal"
    type="revolute">
    <origin
      xyz="1.9709 1.997 2.239"
      rpy="1.5708 0 -1.5708" />
    <parent
      link="base_link" />
    <child
      link="link_signal" />
    <axis
      xyz="0 0 1" />
    <limit
      lower="-3.14"
      upper="3.14"
      effort="100"
      velocity="1" />
    <dynamics
      damping="1"
      friction="0.75" />
  </joint>
  <link
    name="link_switch">
    <inertial>
      <origin
        xyz="1.1519E-15 -7.7716E-16 0.05"
        rpy="0 0 0" />
      <mass
        value="38.518" />
      <inertia
        ixx="1.9965"
        ixy="-1.4555E-14"
        ixz="6.7294E-15"
        iyy="1.9965"
        iyz="-3.9374E-17"
        izz="3.9289" />
    </inertial>
    <visual>
      <origin
        xyz="0 0 0"
        rpy="0 0 0" />
      <geometry>
        <mesh
          filename="package://rm_single/meshes/link_switch.STL" />
      </geometry>
      <material
        name="">
        <color
          rgba="1 1 1 1" />
      </material>
    </visual>
    <collision>
      <origin
        xyz="0 0 0"
        rpy="0 0 0" />
      <geometry>
        <mesh
          filename="package://rm_single/meshes/link_switch.STL" />
      </geometry>
    </collision>
  </link>
  <joint
    name="joint_switch"
    type="continuous">
    <origin
      xyz="1.942 2.0001 1.4555"
      rpy="1.5708 0 -1.5708" />
    <parent
      link="base_link" />
    <child
      link="link_switch" />
    <axis
      xyz="0 0 -1" />
    <limit
      lower="-3.14"
      upper="3.14"
      effort="100"
      velocity="1" />
    <dynamics
      damping="1"
      friction="0.75" />
  </joint>
  <link
    name="link_spinning">
    <inertial>
      <origin
        xyz="-0.0024136 0.23737 -0.010237"
        rpy="0 0 0" />
      <mass
        value="15.722" />
      <inertia
        ixx="0.16729"
        ixy="3.6987E-13"
        ixz="1.7677E-12"
        iyy="0.2467"
        iyz="2.0255E-12"
        izz="0.16729" />
    </inertial>
    <visual>
      <origin
        xyz="0 0 0"
        rpy="0 0 0" />
      <geometry>
        <mesh
          filename="package://rm_single/meshes/link_spinning.STL" />
      </geometry>
      <material
        name="">
        <color
          rgba="0.79216 0.81961 0.93333 1" />
      </material>
    </visual>
    <collision>
      <origin
        xyz="0 0 0"
        rpy="0 0 0" />
      <geometry>
        <mesh
          filename="package://rm_single/meshes/link_spinning.STL" />
      </geometry>
    </collision>
  </link>
  <joint
    name="joint_spinning"
    type="continuous">
    <origin
      xyz="-2.5265 -1.6611 -0.0088161"
      rpy="1.5708 0 3.1416" />
    <parent
      link="base_link" />
    <child
      link="link_spinning" />
    <axis
      xyz="0 -1 0" />
    <limit
      lower="-3.14"
      upper="3.14"
      effort="100"
      velocity="1" />
    <dynamics
      damping="1"
      friction="0.75" />
  </joint>
</robot>
